<mujoco model="X02Lite">
  <compiler angle="radian" meshdir="meshes/" autolimits="true"/>
  <asset>
    <mesh name="pelvis" file="pelvis.STL"/>
    <mesh name="torso_Link" file="torso_Link.STL"/>
    <mesh name="L_shoulder_pitch_Link" file="L_shoulder_pitch_Link.STL"/>
    <mesh name="L_shoulder_roll_Link" file="L_shoulder_roll_Link.STL"/>
    <mesh name="L_shoulder_yaw_Link" file="L_shoulder_yaw_Link.STL"/>
    <mesh name="L_elbow_Link" file="L_elbow_Link.STL"/>
    <mesh name="R_shoulder_pitch_Link" file="R_shoulder_pitch_Link.STL"/>
    <mesh name="R_shoulder_roll_Link" file="R_shoulder_roll_Link.STL"/>
    <mesh name="R_shoulder_yaw_Link" file="R_shoulder_yaw_Link.STL"/>
    <mesh name="R_elbow_Link" file="R_elbow_Link.STL"/>
    <mesh name="Head_Link" file="Head_Link.STL"/>
    <mesh name="Logo_Link" file="Logo_Link.STL"/>
    <mesh name="L_hip_yaw_Link" file="L_hip_yaw_Link.STL"/>
    <mesh name="L_hip_roll_Link" file="L_hip_roll_Link.STL"/>
    <mesh name="L_hip_pitch_Link" file="L_hip_pitch_Link.STL"/>
    <mesh name="L_knee_Link" file="L_knee_Link.STL"/>
    <mesh name="L_ankle_pitch_Link" file="L_ankle_pitch_Link.STL"/>
    <mesh name="R_hip_yaw_Link" file="R_hip_yaw_Link.STL"/>
    <mesh name="R_hip_roll_Link" file="R_hip_roll_Link.STL"/>
    <mesh name="R_hip_pitch_Link" file="R_hip_pitch_Link.STL"/>
    <mesh name="R_knee_Link" file="R_knee_Link.STL"/>
    <mesh name="R_ankle_pitch_Link" file="R_ankle_pitch_Link.STL"/>
  </asset>

  <worldbody>
    <body name="pelvis" pos="0. 0. 0.958">
      <inertial pos="0.00318417 0.000355549 0.203024" quat="0.999979 -0.00108743 0.00636448 -0.000835935" mass="14.5565" diaginertia="0.470129 0.31509 0.207873"/>
      <joint name="pelvis" type="free" limited="false" actuatorfrclimited="false"/>
      <geom type="mesh" contype="0" conaffinity="0" group="1" density="0" rgba="1 1 1 1" mesh="pelvis"/>
      <geom type="mesh" contype="0" conaffinity="0" group="1" density="0" rgba="1 1 1 1" mesh="torso_Link"/>
      <geom pos="0 0.136079 0.306812" quat="0.560986 -0.430459 0.430459 0.560986" type="mesh" contype="0" conaffinity="0" group="1" density="0" rgba="0.2 0.2 0.2 0.9" mesh="L_shoulder_pitch_Link"/>
      <geom pos="0 0.195 0.3226" quat="0 -0.707107 0 0.707107" type="mesh" contype="0" conaffinity="0" group="1" density="0" rgba="1 1 1 1" mesh="L_shoulder_roll_Link"/>
      <geom pos="0 0.195 0.2106" quat="0 -0.707107 0.707107 0" type="mesh" contype="0" conaffinity="0" group="1" density="0" rgba="0.2 0.2 0.2 0.9" mesh="L_shoulder_yaw_Link"/>
      <geom pos="0.01 0.195 0.0376" quat="0.5 0.5 0.5 -0.5" type="mesh" contype="0" conaffinity="0" group="1" density="0" rgba="1 1 1 1" mesh="L_elbow_Link"/>
      <geom pos="0 -0.136079 0.306812" quat="0.560986 0.430459 0.430459 -0.560986" type="mesh" contype="0" conaffinity="0" group="1" density="0" rgba="0.2 0.2 0.2 0.9" mesh="R_shoulder_pitch_Link"/>
      <geom pos="0 -0.195 0.3226" quat="0.707107 0 0.707107 0" type="mesh" contype="0" conaffinity="0" group="1" density="0" rgba="1 1 1 1" mesh="R_shoulder_roll_Link"/>
      <geom pos="0 -0.195 0.2106" quat="0 0.707107 0.707107 0" type="mesh" contype="0" conaffinity="0" group="1" density="0" rgba="0.2 0.2 0.2 0.9" mesh="R_shoulder_yaw_Link"/>
      <geom pos="0.01 -0.195 0.0376" quat="-0.5 0.5 -0.5 -0.5" type="mesh" contype="0" conaffinity="0" group="1" density="0" rgba="1 1 1 1" mesh="R_elbow_Link"/>
      <geom pos="0 0 0.355" quat="1 0 0 0" type="mesh" contype="0" conaffinity="0" group="1" density="0" rgba="0.2 0.2 0.2 0.9" mesh="Head_Link"/>
      <geom type="mesh" contype="0" conaffinity="0" group="1" density="0" rgba="1 0 0 0.8" mesh="Logo_Link"/>
      <site name="imu" pos="0 0 0.17"/>
      <body name="L_hip_yaw_Link" pos="0 0 -0.06">
        <inertial pos="0.000942 0.026834 -0.024386" quat="0.513117 0.858073 0.0197402 -0.0057536" mass="1.758" diaginertia="0.00499014 0.00440486 0.00192288"/>
        <joint name="L_hip_yaw" pos="0 0 0" axis="0 0 1" range="-0.785398 0.785398" actuatorfrcrange="-50 50"/>
        <geom type="mesh" contype="0" conaffinity="0" group="1" density="0" rgba="0.898039 0.917647 0.929412 1" mesh="L_hip_yaw_Link"/>
        <body name="L_hip_roll_Link" pos="0 0.09 -0.0474" quat="0 0.707107 0 -0.707107">
          <inertial pos="0.066798 -0.001559 0.021277" quat="0.50932 0.472466 0.565401 0.444624" mass="1.562" diaginertia="0.00442533 0.00416718 0.00298586"/>
          <joint name="L_hip_roll" pos="0 0 0" axis="0 0 -1" range="-0.261799 0.785398" actuatorfrcrange="-50 50"/>
          <geom type="mesh" contype="0" conaffinity="0" group="1" density="0" rgba="0.898039 0.917647 0.929412 1" mesh="L_hip_roll_Link"/>
          <body name="L_hip_pitch_Link" pos="0.092 -0.001 -2.97933e-05" quat="0.707107 -0.707107 0 0">
            <inertial pos="0.082779 -0.000893 -0.001942" quat="0.501001 0.496721 0.511125 0.490936" mass="1.332" diaginertia="0.0171659 0.0170279 0.000932154"/>
            <joint name="L_hip_pitch" pos="0 0 0" axis="0 0 1" range="-0.523599 2.00713" actuatorfrcrange="-72 72"/>
            <geom type="mesh" contype="0" conaffinity="0" group="1" density="0" rgba="1 1 1 1" mesh="L_hip_pitch_Link"/>
            <body name="L_knee_Link" pos="0.35 -2.97933e-05 0">
              <inertial pos="0.126574 0.002525 -0.000118" quat="-0.0104785 0.706909 0.0120787 0.707124" mass="0.847" diaginertia="0.010827 0.0106712 0.00379418"/>
              <joint name="L_knee_pitch" pos="0 0 0" axis="0 0 1" range="-2.44346 0.0872665" actuatorfrcrange="-150 150"/>
              <geom type="mesh" contype="0" conaffinity="0" group="1" density="0" rgba="0.419608 0.419608 0.419608 1" mesh="L_knee_Link"/>
              <body name="L_ankle_pitch_Link" pos="0.35 0 0">
                <inertial pos="0.027322 0.011889 -0.000237" quat="0.487322 0.518113 -0.480787 0.512757" mass="0.256" diaginertia="0.000981359 0.000891022 0.000132689"/>
                <joint name="L_ankle_pitch" pos="0 0 0" axis="0 0 1" range="-1.39626 1.0472" actuatorfrcrange="-45 45"/>
                <geom type="mesh" contype="0" conaffinity="0" group="1" density="0" rgba="1 1 1 1" mesh="L_ankle_pitch_Link"/>
                <geom size="0.018 0.1245" pos="0.041 0.02 0" quat="0.707107 0.707107 0 0" type="cylinder" rgba="1 1 1 1"/>
<!--                <geom type='capsule' size='0.02' fromto='0.04 0.13 0   0.04 -0.09 0' class='collision-left'/>-->
                <site name="L_ankle_F" type="capsule" size='0.015' fromto='0.045  0.1 0   0.045 0.13 0'/>
                <site name="L_ankle_B" type="capsule" size='0.015' fromto='0.045 -0.09 0  0.045 -0.06 0' />
              </body>
            </body>
          </body>
        </body>
      </body>
      <body name="R_hip_yaw_Link" pos="0 0 -0.1074">
        <inertial pos="0.001115 -0.049187 0.001444" quat="0.711805 0.702146 0.00130777 -0.0179453" mass="0.907" diaginertia="0.00206787 0.00201677 0.000566621"/>
        <joint name="R_hip_yaw" pos="0 0 0" axis="0 0 -1" range="-0.785398 0.785398" actuatorfrcrange="-50 50"/>
        <geom type="mesh" contype="0" conaffinity="0" group="1" density="0" rgba="0.898039 0.917647 0.929412 1" mesh="R_hip_yaw_Link"/>
        <body name="R_hip_roll_Link" pos="0 -0.09 0" quat="0.707107 0 0.707107 0">
          <inertial pos="0.066798 -0.001559 -0.021277" quat="0.472466 0.50932 0.444624 0.565401" mass="1.562" diaginertia="0.00442533 0.00416718 0.00298586"/>
          <joint name="R_hip_roll" pos="0 0 0" axis="0 0 -1" range="-0.261799 0.785398" actuatorfrcrange="-50 50"/>
          <geom type="mesh" contype="0" conaffinity="0" group="1" density="0" rgba="1 1 1 1" mesh="R_hip_roll_Link"/>
          <body name="R_hip_pitch_Link" pos="0.092 -0.001 2.97933e-05" quat="0.707107 -0.707107 0 0">
            <inertial pos="0.082779 0.000893 -0.001942" quat="0.502748 0.499246 0.49272 0.505197" mass="1.332" diaginertia="0.0171659 0.0170279 0.000932154"/>
            <joint name="R_hip_pitch" pos="0 0 0" axis="0 0 -1" range="-0.523599 2.00713" actuatorfrcrange="-72 72"/>
            <geom type="mesh" contype="0" conaffinity="0" group="1" density="0" rgba="1 1 1 1" mesh="R_hip_pitch_Link"/>
            <body name="R_knee_Link" pos="0.35 2.97933e-05 0">
              <inertial pos="0.126574 -0.002525 -0.000118" quat="0.0107495 0.707104 -0.0118079 0.70693" mass="0.847" diaginertia="0.010827 0.0106712 0.00379418"/>
              <joint name="R_knee_pitch" pos="0 0 0" axis="0 0 -1" range="-2.44346 0.0872665" actuatorfrcrange="-150 150"/>
              <geom type="mesh" contype="0" conaffinity="0" group="1" density="0" rgba="0.419608 0.419608 0.419608 1" mesh="R_knee_Link"/>
              <body name="R_ankle_pitch_Link" pos="0.35 0 0">
                <inertial pos="0.027322 -0.011889 -0.000237" quat="0.512559 0.48148 -0.51832 0.486625" mass="0.256" diaginertia="0.000981357 0.000891024 0.000132688"/>
                <joint name="R_ankle_pitch" pos="0 0 0" axis="0 0 -1" range="-1.39626 1.0472" actuatorfrcrange="-45 45"/>
                <geom type="mesh" contype="0" conaffinity="0" group="1" density="0" rgba="1 1 1 1" mesh="R_ankle_pitch_Link"/>
                <geom size="0.018 0.1245" pos="0.041 -0.02 0" quat="0.707107 0.707107 0 0" type="cylinder" rgba="1 1 1 1"/>
<!--                <geom type='capsule' size='0.02' fromto='0.04 0.09 0   0.04 -0.13 0' class='collision-right'/>-->
                <site name="R_ankle_F" type="capsule" size='0.015' fromto='0.045 -0.1 0  0.045 -0.13 0'/>
                <site name="R_ankle_B" type="capsule" size='0.015' fromto='0.045 0.09 0  0.045 0.06 0' />
              </body>
            </body>
          </body>
        </body>
      </body>
    </body>
  </worldbody>

  <actuator>
    <motor name="juL" joint="L_hip_yaw"       gear="1.00" ctrlrange="-300.0 300.0" ctrllimited="true"/> <!-- Leg Left -->
    <motor name="jsL" joint="L_hip_roll"      gear="1.00" ctrlrange="-300.0 300.0" ctrllimited="true"/>
    <motor name="jhL" joint="L_hip_pitch"     gear="1.00" ctrlrange="-300.0 300.0" ctrllimited="true"/>
    <motor name="jkL" joint="L_knee_pitch"    gear="1.00" ctrlrange="-300.0 300.0" ctrllimited="true"/>
    <motor name="jFL" joint="L_ankle_pitch"   gear="1.00" ctrlrange="-300.0 300.0" ctrllimited="true"/>

    <motor name="juR" joint="R_hip_yaw"       gear="1.00" ctrlrange="-300.0 300.0" ctrllimited="true"/> <!-- Leg Right -->
    <motor name="jsR" joint="R_hip_roll"      gear="1.00" ctrlrange="-300.0 300.0" ctrllimited="true"/>
    <motor name="jhR" joint="R_hip_pitch"     gear="1.00" ctrlrange="-300.0 300.0" ctrllimited="true"/>
    <motor name="jkR" joint="R_knee_pitch"    gear="1.00" ctrlrange="-300.0 300.0" ctrllimited="true"/>
    <motor name="jFR" joint="R_ankle_pitch"   gear="1.00" ctrlrange="-300.0 300.0" ctrllimited="true"/>
  </actuator>

  <sensor>
    <!-- 执行器的位置 -->
    <jointpos name="juLp" joint="L_hip_yaw"        noise="0.0"/> <!-- Leg Left -->
    <jointpos name="jsLp" joint="L_hip_roll"       noise="0.0"/>
    <jointpos name="jhLp" joint="L_hip_pitch"      noise="0.0"/>
    <jointpos name="jkLp" joint="L_knee_pitch"     noise="0.0"/>
    <jointpos name="jFLp" joint="L_ankle_pitch"    noise="0.0"/>

    <jointpos name="juRp" joint="R_hip_yaw"        noise="0.0"/> <!-- Leg Right -->
    <jointpos name="jsRp" joint="R_hip_roll"       noise="0.0"/>
    <jointpos name="jhRp" joint="R_hip_pitch"      noise="0.0"/>
    <jointpos name="jkRp" joint="R_knee_pitch"     noise="0.0"/>
    <jointpos name="jFRp" joint="R_ankle_pitch"    noise="0.0"/>

    <!-- 执行器的速度 -->
    <jointvel name="juLv" joint="L_hip_yaw"        noise="0.0"/> <!-- Leg Left -->
    <jointvel name="jsLv" joint="L_hip_roll"       noise="0.0"/>
    <jointvel name="jhLv" joint="L_hip_pitch"      noise="0.0"/>
    <jointvel name="jkLv" joint="L_knee_pitch"     noise="0.0"/>
    <jointvel name="jFLv" joint="L_ankle_pitch"    noise="0.0"/>

    <jointvel name="juRv" joint="R_hip_yaw"        noise="0.0"/> <!-- Leg Right -->
    <jointvel name="jsRv" joint="R_hip_roll"       noise="0.0"/>
    <jointvel name="jhRv" joint="R_hip_pitch"      noise="0.0"/>
    <jointvel name="jkRv" joint="R_knee_pitch"     noise="0.0"/>
    <jointvel name="jFRv" joint="R_ankle_pitch"    noise="0.0"/>

    <!-- 执行器的扭矩电流 -->
    <actuatorfrc name="iuL" actuator="juL" noise="0.0"/> <!-- Leg Left -->
    <actuatorfrc name="isL" actuator="jsL" noise="0.0"/>
    <actuatorfrc name="ihL" actuator="jhL" noise="0.0"/>
    <actuatorfrc name="ikL" actuator="jkL" noise="0.0"/>
    <actuatorfrc name="iFL" actuator="jFL" noise="0.0"/>

    <actuatorfrc name="iuR" actuator="juR" noise="0.0"/> <!-- Leg Right -->
    <actuatorfrc name="isR" actuator="jsR" noise="0.0"/>
    <actuatorfrc name="ihR" actuator="jhR" noise="0.0"/>
    <actuatorfrc name="ikR" actuator="jkR" noise="0.0"/>
    <actuatorfrc name="iFR" actuator="jFR" noise="0.0"/>

    <!-- 身体的的姿态 -->
    <gyro          name="gyro"    site='imu' noise='0.005' cutoff='34.9'/>
    <accelerometer name="acc"     site='imu' noise='0.005' cutoff='157'/>
    <framequat     name='bq'      objtype='site' noise='0.001' objname='imu'/>
    <touch         name="LaF"     site='L_ankle_F'    noise="0" />
    <touch         name="LaB"     site='L_ankle_B'    noise="0" />
    <touch         name="RaF"     site='R_ankle_F'    noise="0" />
    <touch         name="RaB"     site='R_ankle_B'    noise="0" />
  </sensor>
</mujoco>
